<?xml version="1.0"?>
<robot name="simple_robot">

  <!-- BASE -->
  <link name="base_link">
    <visual>
      <geometry>
        <box size="0.5 0.3 0.1"/>
      </geometry>
      <origin xyz="0 0 0.05"/>
    </visual>
  </link>

  <!-- LEFT WHEEL -->
  <link name="left_wheel">
    <visual>
      <geometry>
        <cylinder radius="0.05" length="0.02"/>
      </geometry>
    </visual>
  </link>

  <joint name="left_wheel_joint" type="continuous">
    <parent link="base_link"/>
    <child link="left_wheel"/>
    <origin xyz="0 0.15 0"/>
    <axis xyz="0 1 0"/>
  </joint>

  <!-- RIGHT WHEEL -->
  <link name="right_wheel">
    <visual>
      <geometry>
        <cylinder radius="0.05" length="0.02"/>
      </geometry>
    </visual>
  </link>

  <joint name="right_wheel_joint" type="continuous">
    <parent link="base_link"/>
    <child link="right_wheel"/>
    <origin xyz="0 -0.15 0"/>
    <axis xyz="0 1 0"/>
  </joint>

  <!-- CASTER -->
  <link name="caster_wheel">
    <visual>
      <geometry>
        <sphere radius="0.04"/>
      </geometry>
    </visual>
  </link>

  <joint name="caster_joint" type="fixed">
    <parent link="base_link"/>
    <child link="caster_wheel"/>
    <origin xyz="-0.2 0 -0.05"/>
  </joint>

</robot>